Workbook

Sheet Daftar Perusahaan
A1: DAFTAR PERUSAHAAN JASA TAHUN 2019-2022
A2: 2019 -2022
A3: SEKTOR FINANCIAL
A4: BJTM | B4: Bank Pembangunan Daerah Jawa Timur
A5: BKSW | B5: Bank QNB Indonesia Tbk.
A6: CFIN | B6: Clipan Finance Indonesia Tbk.
A7: LIFE | B7: MSIG Life Insurance Indonesia
A8: FUJI | B8: Fuji Finance Indonesia Tbk.
A9: LPGI | B9: Lippo General Insurance Tbk.
A10: NISP | B10: Bank OCBC NISP Tbk.
A11: NOBU | B11: Bank Nationalnobu Tbk.
A12: OCAP | B12: Onix Capital Tbk.
A13: ABDA | B13: Asuransi Bina Dana Arta Tbk.
A14: ADMF | B14: Adira Dinamika Multi Finance Tbk.
A15: AGRO | B15: Bank Raya Indonesia Tbk.
... A108: BACA | B108: Bank Capital Indonesia Tbk.

Sheet Kriteria 1
A1: Perusahaan jasa keuangan yang terdaftar di Bursa Efek Indonesia (BEI) secara berturut-turut selama periode penelitian yaitu tahun 2019-2022.
A3: No | B3: Kode Perusahaan | C3: Nama Perusahaan | D3: Berurut- urut
A4: 1 | B4: BJTM | C4: Bank Pembangunan Daerah Jawa Timur | D4: v
A5: 2 | B5: BKSW | C5: Bank QNB Indonesia Tbk. | D5: v
A6: 3 | B6: CFIN | C6: Clipan Finance Indonesia Tbk. | D6: v
A7: 4 | B7: LIFE | C7: MSIG Life Insurance Indonesia | D7: v
A8: 5 | B8: FUJI | C8: Fuji Finance Indonesia Tbk. | D8: v
A9: 6 | B9: LPGI | C9: Lippo General Insurance Tbk. | D9: v
A10: 7 | B10: NISP | C10: Bank OCBC NISP Tbk. | D10: v
A11: 8 | B11: NOBU | C11: Bank Nationalnobu Tbk. | D11: v
A12: 9 | B12: OCAP | C12: Onix Capital Tbk. | D12: v
A13: 10 | B13: ABDA | C13: Asuransi Bina Dana Arta Tbk. | D13: v
A14: 11 | B14: ADMF | C14: Adira Dinamika Multi Finance Tbk. | D14: v
A15: 12 | B15: AGRO | C15: Bank Raya Indonesia Tbk. | D15: v
... A108: 105 | B108: BACA | C108: Bank Capital Indonesia Tbk. | D108: v

Sheet Kriteria 2
A1: Perusahaan sarana dan prasarana sektor infrastruktur dan transportasi yang terdaftar di Bursa Efek Indonesia (BEI) yang menerbitkan laporan keuangan tahunan (annual report) secara lengkap dan konsisten dalam periode 2019-2021.
A3: No | B3: Kode Perusahaan | C3: Nama Perusahaan | D3: Tahun | H3: Annual Report
D4: 2019 | E4: 2020 | F4: 2021 | G4: 2022
A5: 1 | B5: BJTM | C5: Bank Pembangunan Daerah Jawa Timur | D5: v | E5: v | F5: v | G5: v | H5: v
A6: 2 | B6: BKSW | C6: Bank QNB Indonesia Tbk. | D6: v | E6: v | F6: v | G6: v | H6: v
A7: 3 | B7: CFIN | C7: Clipan Finance Indonesia Tbk. | D7: v | E7: v | F7: v | G7: v | H7: v
A8: 4 | B8: LIFE | C8: MSIG Life Insurance Indonesia | D8: v | E8: v | F8: v | G8: v | H8: v
A9: 5 | B9: FUJI | C9: Fuji Finance Indonesia Tbk. | D9: v | E9: v | F9: v | G9: v | H9: v
A10: 6 | B10: LPGI | C10: Lippo General Insurance Tbk. | D10: v | E10: v | F10: v | G10: v | H10: v
A11: 7 | B11: NISP | C11: Bank OCBC NISP Tbk. | D11: v | E11: v | F11: v | G11: v | H11: v
A12: 8 | B12: NOBU | C12: Bank Nationalnobu Tbk. | D12: v | E12: v | F12: v | G12: v | H12: v
A13: 9 | B13: OCAP | C13: Onix Capital Tbk. | D13: v | E13: v | F13: v | G13: v | H13: v
A14: 10 | B14: ABDA | C14: Asuransi Bina Dana Arta Tbk. | D14: v | E14: v | F14: v | G14: v | H14: v
A15: 11 | B15: ADMF | C15: Adira Dinamika Multi Finance Tbk. | D15: v | E15: v | F15: v | G15: v | H15: v
A16: 12 | B16: AGRO | C16: Bank Raya Indonesia Tbk. | D16: v | E16: v | F16: v | G16: v | H16: v
... A109: 105 | B109: BACA | C109: Bank Capital Indonesia Tbk. | D109: v | E109: v | F109: v | G109: v | H109: v

Sheet Kriteria 3
A1: Perusahaan yang memiliki laporan keuangan nominal rupiah (Rp).
A3: No | B3: Kode Perusahaan | C3: Nama Perusahaan | D3: Rp
A4: 1 | B4: BJTM | C4: Bank Pembangunan Daerah Jawa Timur | D4: v
A5: 2 | B5: BKSW | C5: Bank QNB Indonesia Tbk. | D5: v
A6: 3 | B6: CFIN | C6: Clipan Finance Indonesia Tbk. | D6: v
A7: 4 | B7: LIFE | C7: MSIG Life Insurance Indonesia | D7: v
A8: 5 | B8: FUJI | C8: Fuji Finance Indonesia Tbk. | D8: v
A9: 6 | B9: LPGI | C9: Lippo General Insurance Tbk. | D9: v
A10: 7 | B10: NISP | C10: Bank OCBC NISP Tbk. | D10: v
A11: 8 | B11: NOBU | C11: Bank Nationalnobu Tbk. | D11: v
A12: 9 | B12: OCAP | C12: Onix Capital Tbk. | D12: v
A13: 10 | B13: ABDA | C13: Asuransi Bina Dana Arta Tbk. | D13: v
A14: 11 | B14: ADMF | C14: Adira Dinamika Multi Finance Tbk. | D14: v
A15: 12 | B15: AGRO | C15: Bank Raya Indonesia Tbk. | D15: v
... A108: 105 | B108: BACA | C108: Bank Capital Indonesia Tbk. | D108: v

Sheet Kriteria 4
A1: Perusahaan JASA KEUANGAN yang menghasilkan laba positif selama periode 2019-2021.
A3: No | B3: Kode Perusahaan | D3: Tahun | H3: Laba +
D4: 2019 | E4: 2020 | F4: 2021 | G4: 2022
A5: 1 | B5: BJTM | C5: Bank Pembangunan Daerah Jawa Timur | D5: v | E5: v | F5: v | G5: v | H5: v
A6: 2 | B6: BKSW | C6: Bank QNB Indonesia Tbk. | D6: v | E6: x | F6: x | G6: x | H6: x
A7: 3 | B7: CFIN | C7: Clipan Finance Indonesia Tbk. | D7: v | E7: v | F7: v | G7: v | H7: v
A8: 4 | B8: LIFE | C8: MSIG Life Insurance Indonesia | D8: v | E8: v | F8: v | G8: v | H8: v
A9: 5 | B9: FUJI | C9: Fuji Finance Indonesia Tbk. | D9: v | E9: v | F9: v | G9: v | H9: v
A10: 6 | B10: LPGI | C10: Lippo General Insurance Tbk. | D10: v | E10: v | F10: v | G10: v | H10: v
A11: 7 | B11: NISP | C11: Bank OCBC NISP Tbk. | D11: v | E11: v | F11: v | G11: v | H11: v
A12: 8 | B12: NOBU | C12: Bank Nationalnobu Tbk. | D12: v | E12: v | F12: v | G12: v | H12: v
A13: 9 | B13: OCAP | C13: Onix Capital Tbk. | D13: x | E13: x | F13: x | G13: x | H13: x
A14: 10 | B14: ABDA | C14: Asuransi Bina Dana Arta Tbk. | D14: v | E14: v | F14: v | G14: v | H14: v
A15: 11 | B15: ADMF | C15: Adira Dinamika Multi Finance Tbk. | D15: v | E15: v | F15: v | G15: v | H15: v
A16: 12 | B16: AGRO | C16: Bank Raya Indonesia Tbk. | D16: v | E16: v | F16: x | G16: v | H16: x
... A37: 33 | B37: BDMN | C37: Bank Danamon Indonesia Tbk. | D37: v | E37: v | F37: v | G37: v | H37: v
A38: 34 | B38: BEKS | C38: Bank Pembangunan Daerah Banten | D38: x | E38: x
A39: 35 | B39: BFIN | C39: BFI Finance Indonesia Tbk. | D39: v | E39: v | F39: v | G39: v | H39: v
A40: 36 | B40: BGTG | C40: Bank Ganesha Tbk. | D40: v | E40: v | F40: v | G40: v | H40: v
A41: 37 | B41: BINA | C41: Bank Ina Perdana Tbk. | D41: v | E41: v | F41: v | G41: v | H41: v
A42: 38 | B42: BJBR | C42: Bank Pembangunan Daerah Jawa B | D42: v | E42: v | F42: v | G42: v | H42: v
A43: 39 | B43: BMAS | C43: Bank Maspion Indonesia Tbk. | D43: v | E43: v | F43: v | G43: v | H43: v
A44: 40 | B44: BMRI | C44: Bank Mandiri (Persero) Tbk. | D44: v | E44: v | F44: v | G44: v | H44: v
A45: 41 | B45: BNBA | C45: Bank Bumi Arta Tbk. | D45: v | E45: v | F45: v | G45: v | H45: v
A46: 42 | B46: BNGA | C46: Bank CIMB Niaga Tbk. | D46: v | E46: v | F46: v | G46: v | H46: v
A47: 43 | B47: BNII | C47: Bank Maybank Indonesia Tbk. | D47: v | E47: v | F47: v | G47: v | H47: v
A48: 44 | B48: BNLI | C48: Bank Permata Tbk. | D48: v | E48: v | F48: v | G48: v | H48: v
A49: 45 | B49: BPFI | C49: Woori Finance Indonesia Tbk. | D49: v | E49: v | F49: v | G49: v | H49: v
A50: 46 | B50: BPII | C50: Batavia Prosperindo Internasional | D50: v | E50: v | F50: v | G50: v | H50: v
... A58: 54 | B58: GSMF | C58: Equity Development Investment | D58: v | E58: v | F58: v | G58: v | H58: v
A59: 55 | B59: HDFA | C59: Radana Bhaskara Finance Tbk. | D59: x | E59: x | G59: x | H59: x
A60: 56 | B60: INPC | C60: Bank Artha Graha Internasional | D60: x | E60: v | F60: x | G60: v | H60: x
A61: 57 | B61: LPPS | C61: Lenox Pasifik Investama Tbk. | D61: x | E61: v | F61: v | G61: x | H61: x
A62: 58 | B62: MAYA | C62: Bank Mayapada Internasional Tbk | D62: v | E62: v | F62: v | G62: x | H62: x
A63: 59 | B63: MCOR | C63: Bank China Construction Bank Indonesia | D63: v | E63: v | F63: v | G63: v | H63: v
A64: 60 | B64: MEGA | C64: Bank Mega Tbk. | D64: v | E64: v | F64: v | G64: v | H64: v
A65: 61 | B65: MFIN | C65: Mandala Multifinance Tbk. | D65: v | E65: v | F65: v | G65: v | H65: v
A66: 62 | B66: MGNA | C66: Magna Investama Mandiri Tbk. | D66: x | E66: v | F66: x | G66: x | H66: x
A67: 63 | B67: MREI | C67: Maskapai Reasuransi Indonesia | D67: v | E67: v | F67: v | G67: x | H67: x
A68: 64 | B68: PADI | C68: Minna Padi Investama Sekuritas | D68: x | E68: x | F68: x | G68: x | H68: x
...

Sheet AUDELAY
A1: No | B1: Kode Perusahaan | C1: Nama Perusahaan | D1: Tahun | E1: Tanggal Laporan Audti | F1: Tanggal Laporan Keuangan | G1: AUDELAY
A2: 1 | B2: BJTM | C2: Bank Pembangunan Daerah Jawa Timur | D2: 2019 | E2: 43860 | F2: 43830 | G2: =30 -> 30
A3: 2 | B3: CFIN | C3: Clipan Finance Indonesia Tbk. | D3: 2019 | E3: 43886 | F3: 43830 | G3: =31+25 -> 56
A4: 3 | B4: LIFE | C4: MSIG Life Insurance Indonesia | D4: 2019 | E4: 43942 | F4: 43830 | G4: =31+29+31+21 -> 112
A5: 4 | B5: FUJI | C5: Fuji Finance Indonesia Tbk. | D5: 2019 | E5: 43889 | F5: 43830 | G5: =31+28 -> 59
A6: 5 | B6: LPGI | C6: Lippo General Insurance Tbk. | D6: 2019 | E6: 43901 | F6: 43830 | G6: =31+28+11 -> 70
A7: 6 | B7: NISP | C7: Bank OCBC NISP Tbk. | D7: 2019 | E7: 43853 | F7: 43830 | G7: =23 -> 23
A8: 7 | B8: NOBU | C8: Bank Nationalnobu Tbk. | D8: 2019 | E8: 43962 | F8: 43830 | G8: =31+28+31+30+11 -> 131
A9: 8 | B9: ABDA | C9: Asuransi Bina Dana Arta Tbk. | D9: 2019 | E9: 43966 | F9: 43830 | G9: =31+29+31+30+15 -> 136
A10: 9 | B10: ADMF | C10: Adira Dinamika Multi Finance Tbk. | D10: 2019 | E10: 43854 | F10: 43830 | G10: =24 -> 24
A11: 10 | B11: AMAG | C11: Asuransi Multi Artha Guna Tbk. | D11: 2019 | E11: 43889 | F11: 43830 | G11: =31+28+30 -> 89
A12: 11 | B12: APIC | C12: Pacific Strategic Financial Tbk | D12: 2019 | E12: 43948 | F12: 43830 | G12: =31+29+31+27 -> 118
A13: 12 | B13: ASBI | C13: Asuransi Bintang Tbk. | D13: 2019 | E13: 43917 | F13: 43830 | G13: =31+29+27 -> 87
A14: 13 | B14: ASDM | C14: Asuransi Dayin Mitra Tbk. | D14: 2019 | E14: 43913 | F14: 43830 | G14: =31+29+23 -> 83
A15: 14 | B15: BBCA | C15: Bank Central Asia Tbk. | D15: 2019 | E15: 43867 | F15: 43830 | G15: =31+6 -> 37
A16: 15 | B16: BBLD | C16: Buana Finance Tbk. | D16: 2019 | E16: 43935 | F16: 43830 | G16: =31+29+31+14 -> 105
A17: 16 | B17: BBMD | C17: Bank Mestika Dharma Tbk. | D17: 2019 | E17: 43910 | F17: 43830 | G17: =31+29+20 -> 80
A18: 17 | B18: BBNI | C18: Bank Negara Indonesia (Persero) | D18: 2019 | E18: 43850 | F18: 43830 | G18: =20 -> 20
A19: 18 | B19: BBRI | C19: Bank Rakyat Indonesia (Persero) | D19: 2019 | E19: 43854 | F19: 43830 | G19: =31+6 -> 37
A20: 19 | B20: BBTN | C20: Bank Tabungan Negara (Persero) | D20: 2019 | E20: 43875 | F20: 43830 | G20: =31+14 -> 45
A21: 20 | B21: BCAP | C21: MNC Kapital Indonesia Tbk. | D21: 2019 | E21: 43916 | F21: 43830 | G21: =31+29+26 -> 86
A22: 21 | B22: BDMN | C22: Bank Danamon Indonesia Tbk. | D22: 2019 | E22: 43857 | F22: 43830 | G22: =27 -> 27
A23: 22 | B23: BFIN | C23: BFI Finance Indonesia Tbk. | D23: 2019 | E23: 43880 | F23: 43830 | G23: =31+19 -> 50
A24: 23 | B24: BGTG | C24: Bank Ganesha Tbk. | D24: 2019 | E24: 43927 | F24: 43830 | G24: =31+28+31+6 -> 96
A25: 24 | B25: BINA | C25: Bank Ina Perdana Tbk. | D25: 2019 | E25: 43965 | F25: 43830 | G25: =31+28+31+30+14 -> 134
A26: 25 | B26: BJBR | C26: Bank Pembangunan Daerah Jawa Barat | D26: 2019 | E26: 43889 | F26: 43830 | G26: =31+28 -> 59
A27: 26 | B27: BMAS | C27: Bank Maspion Indonesia Tbk. | D27: 2019 | E27: 43880 | F27: 43830 | G27: =31+19 -> 50
A28: 27 | B28: BMRI | C28: Bank Mandiri (Persero) Tbk. | D28: 2019 | E28: 43853 | F28: 43830 | G28: =23 -> 23
A29: 28 | B29: BNBA | C29: Bank Bumi Arta Tbk. | D29: 2019 | E29: 43921 | F29: 43830 | G29: =31+29+31 -> 91
A30: 29 | B30: BNGA | C30: Bank CIMB Niaga Tbk. | D30: 2019 | E30: 43878 | F30: 43830 | G30: =31+17 -> 48
A31: 30 | B31: BNII | C31: Bank Maybank Indonesia Tbk. | D31: 2019 | E31: 43878 | F31: 43830 | G31: =31+17 -> 48
A32: 31 | B32: BNLI | C32: Bank Permata Tbk. | D32: 2019 | E32: 43879 | F32: 43830 | G32: =31+18 -> 49
A33: 32 | B33: BPFI | C33: Woori Finance Indonesia Tbk. | D33: 2019 | E33: 43895 | F33: 43830 | G33: =31+29+5 -> 65
A34: 33 | B34: BPII | C34: Batavia Prosperindo Internasional | D34: 2019 | E34: 43906 | F34: 43830 | G34: =31+29+16 -> 76
A35: 34 | B35: BTPN | C35: Bank BTPN Tbk. | D35: 2019 | E35: 43913 | F35: 43830 | G35: =31+29+23 -> 83
A36: 35 | B36: DNET | C36: Indoritel Makmur Internasional | D36: 2019 | E36: 43978 | F36: 43830 | G36: =31+29+31+30+27 -> 148
A37: 36 | B37: GSMF | C37: Equity Development Investment | D37: 2019 | E37: 43963 | F37: 43830 | G37: =31+29+31+30+12 -> 133
A38: 37 | B38: MCOR | C38: Bank China Construction Bank Indonesia | D38: 2019 | E38: 43921 | F38: 43830 | G38: =31+29+31 -> 91
A39: 38 | B39: MEGA | C39: Bank Mega Tbk. | D39: 2019 | E39: 43964 | F39: 43830 | G39: =31+29+31+30+13 -> 134
A40: 39 | B40: MFIN | C40: Mandala Multifinance Tbk. | D40: 2019 | E40: 43907 | F40: 43830 | G40: =31+29+17 -> 77
...

Sheet SIZE
A1: No | B1: Kode Perusahaan | C1: Nama Perusahaan | D1: Tahun | E1: Total Aktiva | F1: UP
A2: 1 | B2: BJTM | C2: Bank Pembangunan Daerah Jawa Timur | D2: 2019 | E2: 76715290000000 | F2: =LN(E2) -> 31.971122
A3: 2 | B3: CFIN | C3: Clipan Finance Indonesia Tbk. | D3: 2019 | E3: 12117478069 | F3: =LN(E3) -> 23.217915
A4: 3 | B4: LIFE | C4: MSIG Life Insurance Indonesia | D4: 2019 | E4: 3475230000000 | F4: =LN(E4) -> 28.876682
A5: 4 | B5: FUJI | C5: Fuji Finance Indonesia Tbk. | D5: 2019 | E5: 136698444824 | F5: =LN(E5) -> 25.641043
A6: 5 | B6: LPGI | C6: Lippo General Insurance Tbk. | D6: 2019 | E6: 2423706043201 | F6: =LN(E6) -> 28.516319
A7: 6 | B7: NISP | C7: Bank OCBC NISP Tbk. | D7: 2019 | E7: 180706987000000 | F7: =LN(E7) -> 32.827898
A8: 7 | B8: NOBU | C8: Bank Nationalnobu Tbk. | D8: 2019 | E8: 13147503000000 | F8: =LN(E8) -> 30.207253
A9: 8 | B9: ABDA | C9: Asuransi Bina Dana Arta Tbk. | D9: 2019 | E9: 2579654391000 | F9: =LN(E9) -> 28.578677
A10: 9 | B10: ADMF | C10: Adira Dinamika Multi Finance Tbk. | D10: 2019 | E10: 35116853000000 | F10: =LN(E10) -> 31.189702
A11: 10 | B11: AMAG | C11: Asuransi Multi Artha Guna Tbk. | D11: 2019 | E11: 4626630367000 | F11: =LN(E11) -> 29.16285
A12: 11 | B12: APIC | C12: Pacific Strategic Financial Tbk | D12: 2019 | E12: 3652947899747 | F12: =LN(E12) -> 28.926556
A13: 12 | B13: ASBI | C13: Asuransi Bintang Tbk. | D13: 2019 | E13: 857520585000 | F13: =LN(E13) -> 27.477311
... A126: 125 | B126: BJTM | C126: Bank Pembangunan Daerah Jawa Timur | D126: 2021 | E126: 100723330000000 | F126: =LN(E126) -> 32.243399
A127: 126 | B127: CFIN | C127: Clipan Finance Indonesia Tbk. | D127: 2021 | E127: =7123904019000+0 -> 7123904019000 | F127: =LN(E127) -> 29.594477
A128: 127 | B128: LIFE | C128: MSIG Life Insurance Indonesia | D128: 2021 | E128: =5087106000000+0 -> 5087106000000 | F128: =LN(E128) -> 29.25773
A129: 128 | B129: FUJI | C129: Fuji Finance Indonesia Tbk. | D129: 2021 | E129: 153713575228 | F129: =LN(E129) -> 25.758357
A130: 129 | B130: LPGI | C130: Lippo General Insurance Tbk. | D130: 2021 | E130: 2923286260687 | F130: =LN(E130) -> 28.70373
A131: 130 | B131: NISP | C131: Bank OCBC NISP Tbk. | D131: 2021 | E131: 214395608000000 | F131: =LN(E131) -> 32.998844
A132: 131 | B132: NOBU | C132: Bank Nationalnobu Tbk. | D132: 2021 | E132: 20742643000000 | F132: =LN(E132) -> 30.663213
A133: 132 | B133: ABDA | C133: Asuransi Bina Dana Arta Tbk. | D133: 2021 | E133: 2501390090000 | F133: =LN(E133) -> 28.547868
A134: 133 | B134: ADMF | C134: Adira Dinamika Multi Finance Tbk. | D134: 2021 | E134: 23725885000000 | F134: =LN(E134) -> 30.797588
A135: 134 | B135: AMAG | C135: Asuransi Multi Artha Guna Tbk. | D135: 2021 | E135: 4652817906000 | F135: =LN(E135) -> 29.168494
A136: 135 | B136: APIC | C136: Pacific Strategic Financial Tb | D136: 2021 | E136: 5936609239750 | F136: =LN(E136) -> 29.412159
A137: 136 | B137: ASBI | C137: Asuransi Bintang Tbk. | D137: 2021 | E137: 954657152000 | F137: =LN(E137) -> 27.584618
A138: 137 | B138: ASDM | C138: Asuransi Dayin Mitra Tbk. | D138: 2021 | E138: 822740369000 | F138: =LN(E138) -> 27.435907
A139: 138 | B139: BBCA | C139: Bank Central Asia Tbk. | D139: 2021 | E139: 1.2283447e+15 | F139: =LN(E139) -> 34.744444
A140: 139 | B140: BBLD | C140: Buana Finance Tbk. | D140: 2021 | E140: 3582868000000 | F140: =LN(E140) -> 28.907185
... A249: 248 | B249: BACA | C249: Bank Capital Indonesia Tbk. | D249: 2022 | E249: 20628501000000 | F249: =LN(E249) -> 30.657695
A250: 249
A251: 250
A252: 251
A253: 252
A254: 253
A255: 254
A256: 255
A257: 256

Sheet ROA
A1: No | B1: Kode Perusahaan | C1: Nama Perusahaan | D1: Tahun | E1: Laba Bersih Setelah Pajak | F1: Total Aktiva | G1: ROA
A2: 1 | B2: BJTM | C2: Bank Pembangunan Daerah Jawa Timur | D2: 2019 | E2: 1376505000000 | F2: 76715290000000 | G2: =E2/F2 -> 0.017943033
A3: 2 | B3: CFIN | C3: Clipan Finance Indonesia Tbk. | D3: 2019 | E3: =361596020 -> 361596020 | F3: 12117478069 | G3: =E3/F3 -> 0.029840864
A4: 3 | B4: LIFE | C4: MSIG Life Insurance Indonesia | D4: 2019 | E4: 133709000000 | F4: 3475230000000 | G4: =E4/F4 -> 0.038474864
A5: 4 | B5: FUJI | C5: Fuji Finance Indonesia Tbk. | D5: 2019 | E5: 5951348123 | F5: 136698444824 | G5: =E5/F5 -> 0.043536326
A6: 5 | B6: LPGI | C6: Lippo General Insurance Tbk. | D6: 2019 | E6: 80002543527 | F6: 2423706043201 | G6: =E6/F6 -> 0.033008353
A7: 6 | B7: NISP | C7: Bank OCBC NISP Tbk. | D7: 2019 | E7: 2939243000000 | F7: 180706987000000 | G7: =E7/F7 -> 0.016265243
A8: 7 | B8: NOBU | C8: Bank Nationalnobu Tbk. | D8: 2019 | E8: 45794000000 | F8: 13147503000000 | G8: =E8/F8 -> 0.0034830949
A9: 8 | B9: ABDA | C9: Asuransi Bina Dana Arta Tbk. | D9: 2019 | E9: 87524342000 | F9: 2579654391000 | G9: =E9/F9 -> 0.033928709
A10: 9 | B10: ADMF | C10: Adira Dinamika Multi Finance Tbk. | D10: 2019 | E10: 2108691000000 | F10: 35116853000000 | G10: =E10/F10 -> 0.060047835
A11: 10 | B11: AMAG | C11: Asuransi Multi Artha Guna Tbk. | D11: 2019 | E11: 73060310000 | F11: 4626630367000 | G11: =E11/F11 -> 0.015791257
A12: 11 | B12: APIC | C12: Pacific Strategic Financial Tbk | D12: 2019 | E12: 102897273401 | F12: 3652947899747 | G12: =E12/F12 -> 0.028168284
A13: 12 | B13: ASBI | C13: Asuransi Bintang Tbk. | D13: 2019 | E13: 8009060000 | F13: 871769183000 | G13: =E13/F13 -> 0.0091871337
A14: 13 | B14: ASDM | C14: Asuransi Dayin Mitra Tbk. | D14: 2019 | E14: 27839061000 | F14: 1158038755000 | G14: =E14/F14 -> 0.024039835
A15: 14 | B15: BBCA | C15: Bank Central Asia Tbk. | D15: 2019 | E15: 28569974000000 | F15: 918989312000000 | G15: =E15/F15 -> 0.031088473
... A64: 63 | B64: BJTM | C64: Bank Pembangunan Daerah Jawa Timur | D64: 2020 | E64: 1488962000000 | F64: 83619452000000 | G64: =E64/F64 -> 0.017806407
A65: 64 | B65: CFIN | C65: Clipan Finance Indonesia Tbk. | D65: 2020 | E65: =46566702 -> 46566702 | F65: 10917456216 | G65: =E65/F65 -> 0.0042653436
A66: 65 | B66: LIFE | C66: MSIG Life Insurance Indonesia | D66: 2020 | E66: 73038000000 | F66: 5184821000000 | G66: =E66/F66 -> 0.014086889
A67: 66 | B67: FUJI | C67: Fuji Finance Indonesia Tbk. | D67: 2020 | E67: 4897849567 | F67: 141322097298 | G67: =E67/F67 -> 0.034657351
A68: 67 | B68: LPGI | C68: Lippo General Insurance Tbk. | D68: 2020 | E68: 92908485040 | F68: 2815578393095 | G68: =E68/F68 -> 0.03299801
A69: 68 | B69: NISP | C69: Bank OCBC NISP Tbk. | D69: 2020 | E69: 2101671000000 | F69: 206297200000000 | G69: =E69/F69 -> 0.010187589
A70: 69 | B70: NOBU | C70: Bank Nationalnobu Tbk. | D70: 2020 | E70: 53607000000 | F70: 13737934000000 | G70: =E70/F70 -> 0.0039021151
A71: 70 | B71: ABDA | C71: Asuransi Bina Dana Arta Tbk. | D71: 2020 | E71: 138367490000 | F71: 2467880020000 | G71: =E71/F71 -> 0.056067349
A72: 71 | B72: ADMF | C72: Adira Dinamika Multi Finance Tbk. | D72: 2020 | E72: 281576000000 | F72: 8441051000000 | G72: =E72/F72 -> 0.033357931
A73: 72 | B73: AMAG | C73: Asuransi Multi Artha Guna Tbk. | D73: 2020 | E73: 107253266000 | F73: 4737130041000 | G73: =E73/F73 -> 0.02264098
A74: 73 | B74: APIC | C74: Pacific Strategic Financial Tb | D74: 2020 | E74: 124726300324 | F74: 4881911874208 | G74: =E74/F74 -> 0.025548659
A75: 74 | B75: ASBI | C75: Asuransi Bintang Tbk. | D75: 2020 | E75: 23668304000 | F75: 871769183000 | G75: =E75/F75 -> 0.027149737
A76: 75 | B76: ASDM | C76: Asuransi Dayin Mitra Tbk. | D76: 2020 | E76: 26804614000 | F76: 859876511000 | G76: =E76/F76 -> 0.031172632
A77: 76 | B77: BBCA | C77: Bank Central Asia Tbk. | D77: 2020 | E77: 27147109000000 | F77: 1.0755703e+15 | G77: =E77/F77 -> 0.025239736
... A126: 125 | B126: BJTM | C126: Bank Pembangunan Daerah Jawa Timur | D126: 2021 | E126: 1523070000000 | F126: 100723330000000 | G126: =E126/F126 -> 0.015121323
A127: 126 | B127: CFIN | C127: Clipan Finance Indonesia Tbk. | D127: 2021 | E127: 46306100000 | F127: =7123904019000+0 -> 7123904019000 | G127: =E127/F127 -> 0.0065001016
A128: 127 | B128: LIFE | C128: MSIG Life Insurance Indonesia | D128: 2021 | E128: 168683000000 | F128: =5087106000000+0 -> 5087106000000 | G128: =E128/F128 -> 0.033158932
A129: 128 | B129: FUJI | C129: Fuji Finance Indonesia Tbk. | D129: 2021 | E129: 9199918110 | F129: 153713575228 | G129: =E129/F129 -> 0.059851045
A130: 129 | B130: LPGI | C130: Lippo General Insurance Tbk. | D130: 2021 | E130: 98384767320 | F130: 2923286260687 | G130: =E130/F130 -> 0.033655536
A131: 130 | B131: NISP | C131: Bank OCBC NISP Tbk. | D131: 2021 | E131: 2519619000000 | F131: 214395608000000 | G131: =E131/F131 -> 0.011752195
A132: 131 | B132: NOBU | C132: Bank Nationalnobu Tbk. | D132: 2021 | E132: 64186000000 | F132: 20742643000000 | G132: =E132/F132 -> 0.0030943983
A133: 132 | B133: ABDA | C133: Asuransi Bina Dana Arta Tbk. | D133: 2021 | E133: 159144910000 | F133: 2501390090000 | G133: =E133/F133 -> 0.063622588
A134: 133 | B134: ADMF | C134: Adira Dinamika Multi Finance Tbk. | D134: 2021 | E134: 1212700000000 | F134: 23725885000000 | G134: =E134/F134 -> 0.051112951
A135: 134 | B135: AMAG | C135: Asuransi Multi Artha Guna Tbk. | D135: 2021 | E135: 149438469000 | F135: 4652817906000 | G135: =E135/F135 -> 0.032117842
A136: 135 | B136: APIC | C136: Pacific Strategic Financial Tb | D136: 2021 | E136: 102955189353 | F136: 5936609239750 | G136: =E136/F136 -> 0.017342423
...

Sheet DAR
A1: No | B1: Kode Perusahaan | C1: Nama Perusahaan | D1: Tahun | E1: Total Liabilitas | F1: Total Assets | G1: DAR
A2: 1 | B2: BJTM | C2: Bank Pembangunan Daerah Jawa Timur | D2: 2019 | E2: 67529638000000 | F2: 76715290000000 | G2: =E2/F2 -> 0.88026309
A3: 2 | B3: CFIN | C3: Clipan Finance Indonesia Tbk. | D3: 2019 | E3: 6172266324 | F3: 12117478069 | G3: =E3/F3 -> 0.50936889
A4: 3 | B4: LIFE | C4: MSIG Life Insurance Indonesia | D4: 2019 | E4: 2523111000000 | F4: 3475230000000 | G4: =E4/F4 -> 0.72602705
A5: 4 | B5: FUJI | C5: Fuji Finance Indonesia Tbk. | D5: 2019 | E5: 1124920540 | F5: 136698444824 | G5: =E5/F5 -> 0.0082292124
A6: 5 | B6: LPGI | C6: Lippo General Insurance Tbk. | D6: 2019 | E6: 1575194310012 | F6: 2423706043201 | G6: =E6/F6 -> 0.64991145
A7: 6 | B7: NISP | C7: Bank OCBC NISP Tbk. | D7: 2019 | E7: 153042184000000 | F7: 180706987000000 | G7: =E7/F7 -> 0.84690795
A8: 7 | B8: NOBU | C8: Bank Nationalnobu Tbk. | D8: 2019 | E8: 11683086000000 | F8: 13147503000000 | G8: =E8/F8 -> 0.88861634
A9: 8 | B9: ABDA | C9: Asuransi Bina Dana Arta Tbk. | D9: 2019 | E9: 1325948582000 | F9: 2579654391000 | G9: =E9/F9 -> 0.51400241
A10: 9 | B10: ADMF | C10: Adira Dinamika Multi Finance Tbk. | D10: 2019 | E10: 27038058000000 | F10: 35116853000000 | G10: =E10/F10 -> 0.76994536
A11: 10 | B11: AMAG | C11: Asuransi Multi Artha Guna Tbk. | D11: 2019 | E11: 2675535753000 | F11: 4626630367000 | G11: =E11/F11 -> 0.57829036
A12: 11 | B12: APIC | C12: Pacific Strategic Financial Tbk | D12: 2019 | E12: 1818115863373 | F12: 3652947899747 | G12: =E12/F12 -> 0.49771196
A13: 12 | B13: ASBI | C13: Asuransi Bintang Tbk. | D13: 2019 | E13: 566035087000 | F13: 857520585000 | G13: =E13/F13 -> 0.66008338
... A126: 125 | B126: BJTM | C126: Bank Pembangunan Daerah Jawa Timur | D126: 2021 | E126: 89812791000000 | F126: 100723330000000 | G126: =E126/F126 -> 0.89167813
A127: 126 | B127: CFIN | C127: Clipan Finance Indonesia Tbk. | D127: 2021 | E127: 2317783818000 | F127: =7123904019000+0 -> 7123904019000 | G127: =E127/F127 -> 0.32535304
A128: 127 | B128: LIFE | C128: MSIG Life Insurance Indonesia | D128: 2021 | E128: 3990215000000 | F128: =5087106000000+0 -> 5087106000000 | G128: =E128/F128 -> 0.78437819
A129: 128 | B129: FUJI | C129: Fuji Finance Indonesia Tbk. | D129: 2021 | E129: 4296566297 | F129: 153713575228 | G129: =E129/F129 -> 0.027951769
A130: 129 | B130: LPGI | C130: Lippo General Insurance Tbk. | D130: 2021 | E130: 2051451547356 | F130: 2923286260687 | G130: =E130/F130 -> 0.70176211
A131: 130 | B131: NISP | C131: Bank OCBC NISP Tbk. | D131: 2021 | E131: 182068037000000 | F131: 214395608000000 | G131: =E131/F131 -> 0.84921533
A132: 131 | B132: NOBU | C132: Bank Nationalnobu Tbk. | D132: 2021 | E132: 18977960000000 | F132: 20742643000000 | G132: =E132/F132 -> 0.91492487
A133: 132 | B133: ABDA | C133: Asuransi Bina Dana Arta Tbk. | D133: 2021 | E133: 983756580000 | F133: 2501390090000 | G133: =E133/F133 -> 0.39328395
A134: 133 | B134: ADMF | C134: Adira Dinamika Multi Finance Tbk. | D134: 2021 | E134: 14838879000000 | F134: 23725885000000 | G134: =E134/F134 -> 0.62542995
A135: 134 | B135: AMAG | C135: Asuransi Multi Artha Guna Tbk. | D135: 2021 | E135: 2793055857000 | F135: 4652817906000 | G135: =E135/F135 -> 0.60029339
A136: 135 | B136: APIC | C136: Pacific Strategic Financial Tb | D136: 2021 | E136: 3824141372207 | F136: 5936609239750 | G136: =E136/F136 -> 0.64416255
A137: 136 | B137: ASBI | C137: Asuransi Bintang Tbk. | D137: 2021 | E137: 598914685000 | F137: 954657152000 | G137: =E137/F137 -> 0.62736102
A138: 137 | B138: ASDM | C138: Asuransi Dayin Mitra Tbk. | D138: 2021 | E138: 461044434000 | F138: 822740369000 | G138: =E138/F138 -> 0.56037658
A139: 138 | B139: BBCA | C139: Bank Central Asia Tbk. | D139: 2021 | E139: 1.0197738e+15 | F139: 1.2283447e+15 | G139: =E139/F139 -> 0.83020163
A140: 139 | B140: BBLD | C140: Buana Finance Tbk. | D140: 2021 | E140: 2339047000000 | F140: 3582868000000 | G140: =E140/F140 -> 0.65284208
... A249: 248 | B249: BACA | C249: Bank Capital Indonesia Tbk. | D249: 2022 | E249: 17340964000000 | F249: 20628501000000 | G249: =E249/F249 -> 0.84063132
A250: 249
A251: 250
A252: 251
A253: 252

Sheet KAP
A1: No | B1: Kode Perusahaan | C1: Nama Perusahaan | D1: Tahun | E1: kode
A2: 1 | B2: BJTM | C2: Bank Pembangunan Daerah Jawa Timur | D2: 2019 | E2: 0
A3: 2 | B3: CFIN | C3: Clipan Finance Indonesia Tbk. | D3: 2019 | E3: 1
A4: 3 | B4: LIFE | C4: MSIG Life Insurance Indonesia | D4: 2019 | E4: 1
A5: 4 | B5: FUJI | C5: Fuji Finance Indonesia Tbk. | D5: 2019 | E5: 0
A6: 5 | B6: LPGI | C6: Lippo General Insurance Tbk. | D6: 2019 | E6: 1
A7: 6 | B7: NISP | C7: Bank OCBC NISP Tbk. | D7: 2019 | E7: 1
A8: 7 | B8: NOBU | C8: Bank Nationalnobu Tbk. | D8: 2019 | E8: 0
A9: 8 | B9: ABDA | C9: Asuransi Bina Dana Arta Tbk. | D9: 2019 | E9: 0
A10: 9 | B10: ADMF | C10: Adira Dinamika Multi Finance Tbk. | D10: 2019 | E10: 1
A11: 10 | B11: AMAG | C11: Asuransi Multi Artha Guna Tbk. | D11: 2019 | E11: 0
A12: 11 | B12: APIC | C12: Pacific Strategic Financial Tbk | D12: 2019 | E12: 0
A13: 12 | B13: ASBI | C13: Asuransi Bintang Tbk. | D13: 2019 | E13: 0
... A249: 248 | B249: BACA | C249: Bank Capital Indonesia Tbk. | D249: 2022 | E249: 0
A250: 249
A251: 250
A252: 251
A253: 252
A254: 253
A255: 254
A256: 255
A257: 256

Sheet OA
A1: No | B1: Kode Perusahaan | C1: Nama Perusahaan | D1: Tahun | E1: kode
A2: 1 | B2: BJTM | C2: Bank Pembangunan Daerah Jawa Timur | D2: 2019 | E2: 1
A3: 2 | B3: CFIN | C3: Clipan Finance Indonesia Tbk. | D3: 2019 | E3: 1
A4: 3 | B4: LIFE | C4: MSIG Life Insurance Indonesia | D4: 2019 | E4: 1
A5: 4 | B5: FUJI | C5: Fuji Finance Indonesia Tbk. | D5: 2019 | E5: 1
A6: 5 | B6: LPGI | C6: Lippo General Insurance Tbk. | D6: 2019 | E6: 1
A7: 6 | B7: NISP | C7: Bank OCBC NISP Tbk. | D7: 2019 | E7: 1
A8: 7 | B8: NOBU | C8: Bank Nationalnobu Tbk. | D8: 2019 | E8: 1
A9: 8 | B9: ABDA | C9: Asuransi Bina Dana Arta Tbk. | D9: 2019 | E9: 1
A10: 9 | B10: ADMF | C10: Adira Dinamika Multi Finance Tbk. | D10: 2019 | E10: 1
A11: 10 | B11: AMAG | C11: Asuransi Multi Artha Guna Tbk. | D11: 2019 | E11: 1
A12: 11 | B12: APIC | C12: Pacific Strategic Financial Tbk | D12: 2019 | E12: 1
A13: 12 | B13: ASBI | C13: Asuransi Bintang Tbk. | D13: 2019 | E13: 1
... A249: 248 | B249: BACA | C249: Bank Capital Indonesia Tbk. | D249: 2022 | E249: 1
A250: 249
A251: 250
A252: 251
A253: 252
A254: 253
A255: 254
A256: 255
A257: 256

Sheet Tabulasi Data
A1: No | B1: Kode Perusahaan | C1: Nama Perusahaan | D1: Tahun | E1: AUDELAY | F1: SIZE | G1: ROA | H1: DAR | I1: KA | J1: OA
A2: 1 | B2: BJTM | C2: Bank Pembangunan Daerah Jawa Timur | D2: 2019 | E2: =AUDELAY!G2 -> 30 | F2: =SIZE!F2 -> 31.971122 | G2: =ROA!G2 -> 0.017943033 | H2: =DAR!G2 -> 0.88026309 | I2: =KAP!E2 -> 0 | J2: =OA!E2 -> 1
A3: 2 | B3: CFIN | C3: Clipan Finance Indonesia Tbk. | D3: 2019 | E3: =AUDELAY!G3 -> 56 | F3: =SIZE!F3 -> 23.217915 | G3: =ROA!G3 -> 0.029840864 | H3: =DAR!G3 -> 0.50936889 | I3: =KAP!E3 -> 1 | J3: =OA!E3 -> 1
A4: 3 | B4: LIFE | C4: MSIG Life Insurance Indonesia | D4: 2019 | E4: =AUDELAY!G4 -> 112 | F4: =SIZE!F4 -> 28.876682 | G4: =ROA!G4 -> 0.038474864 | H4: =DAR!G4 -> 0.72602705 | I4: =KAP!E4 -> 1 | J4: =OA!E4 -> 1
A5: 4 | B5: FUJI | C5: Fuji Finance Indonesia Tbk. | D5: 2019 | E5: =AUDELAY!G5 -> 59 | F5: =SIZE!F5 -> 25.641043 | G5: =ROA!G5 -> 0.043536326 | H5: =DAR!G5 -> 0.0082292124 | I5: =KAP!E5 -> 0 | J5: =OA!E5 -> 1
A6: 5 | B6: LPGI | C6: Lippo General Insurance Tbk. | D6: 2019 | E6: =AUDELAY!G6 -> 70 | F6: =SIZE!F6 -> 28.516319 | G6: =ROA!G6 -> 0.033008353 | H6: =DAR!G6 -> 0.64991145 | I6: =KAP!E6 -> 1 | J6: =OA!E6 -> 1
A7: 6 | B7: NISP | C7: Bank OCBC NISP Tbk. | D7: 2019 | E7: =AUDELAY!G7 -> 23 | F7: =SIZE!F7 -> 32.827898 | G7: =ROA!G7 -> 0.016265243 | H7: =DAR!G7 -> 0.84690795 | I7: =KAP!E7 -> 1 | J7: =OA!E7 -> 1
A8: 7 | B8: NOBU | C8: Bank Nationalnobu Tbk. | D8: 2019 | E8: =AUDELAY!G8 -> 131 | F8: =SIZE!F8 -> 30.207253 | G8: =ROA!G8 -> 0.0034830949 | H8: =DAR!G8 -> 0.88861634 | I8: =KAP!E8 -> 0 | J8: =OA!E8 -> 1
A9: 8 | B9: ABDA | C9: Asuransi Bina Dana Arta Tbk. | D9: 2019 | E9: =AUDELAY!G9 -> 136 | F9: =SIZE!F9 -> 28.578677 | G9: =ROA!G9 -> 0.033928709 | H9: =DAR!G9 -> 0.51400241 | I9: =KAP!E9 -> 0 | J9: =OA!E9 -> 1
A10: 9 | B10: ADMF | C10: Adira Dinamika Multi Finance Tbk. | D10: 2019 | E10: =AUDELAY!G10 -> 24 | F10: =SIZE!F10 -> 31.189702 | G10: =ROA!G10 -> 0.060047835 | H10: =DAR!G10 -> 0.76994536 | I10: =KAP!E10 -> 1 | J10: =OA!E10 -> 1
A11: 10 | B11: AMAG | C11: Asuransi Multi Artha Guna Tbk. | D11: 2019 | E11: =AUDELAY!G11 -> 89 | F11: =SIZE!F11 -> 29.16285 | G11: =ROA!G11 -> 0.015791257 | H11: =DAR!G11 -> 0.57829036 | I11: =KAP!E11 -> 0 | J11: =OA!E11 -> 1
A12: 11 | B12: APIC | C12: Pacific Strategic Financial Tbk | D12: 2019 | E12: =AUDELAY!G12 -> 118 | F12: =SIZE!F12 -> 28.926556 | G12: =ROA!G12 -> 0.028168284 | H12: =DAR!G12 -> 0.49771196 | I12: =KAP!E12 -> 0 | J12: =OA!E12 -> 1
A13: 12 | B13: ASBI | C13: Asuransi Bintang Tbk. | D13: 2019 | E13: =AUDELAY!G13 -> 87 | F13: =SIZE!F13 -> 27.477311 | G13: =ROA!G13 -> 0.0091871337 | H13: =DAR!G13 -> 0.66008338 | I13: =KAP!E13 -> 0 | J13: =OA!E13 -> 1
... A249: 248 | B249: BACA | C249: Bank Capital Indonesia Tbk. | D249: 2022 | E249: =AUDELAY!G249 -> 89 | F249: =SIZE!F249 -> 30.657695 | G249: =ROA!G249 -> 0.0015575053 | H249: =DAR!G249 -> 0.84063132 | I249: =KAP!E249 -> 0 | J249: =OA!E249 -> 1
